Workbook

Sheet Semester A
A1: Lesson # | B1: Lesson Title | C1: Essential Question | D1: Objectives | E1: DOK Level | F1: Prerequisites | G1: Key Words | H1: Suggested Lesson Vocabulary with Definitions | I1: Suggested Activities | J1: Discussion Topic | K1: Lesson Examples | L1: Helpful Notes | M1: Pennsylvania Standards | N1: California Standards | O1: Texas Standards | P1: Florida Standards | Q1: National Standards
A2: 1 | B2: Module Name Here | D2: Students will: | F2: Students must be able to:
A3: 1.1
A4: 1.2
A5: 1.3
A6: 1.4
A7: 1.5
A8: 1.6
A9: 1.7
A10: 1.8
A11: 1.9
A12: 1.10
A13: 2 | B13: Module Name Here | D13: Students will: | F13: Students must be able to:
A14: 2.1
A15: 2.2
A16: 2.3
A17: 2.4
A18: 2.5
A19: 2.6
A20: 2.7
A21: 2.8
A22: 2.9
A23: 2.10
A24: 3 | B24: Module Name Here | D24: Students will: | F24: Students must be able to:
A25: 3.1
A26: 3.2
A27: 3.3
A28: 3.4
A29: 3.5
A30: 3.6
A31: 3.7
A32: 3.8
A33: 3.9
A34: 3.10
A35: 4 | B35: Module Name Here | D35: Students will: | F35: Students must be able to:
A36: 4.1
A37: 4.2
A38: 4.3
A39: 4.4
A40: 4.5
...

Sheet Semester B
A1: Lesson # | B1: Lesson Title | C1: Essential Question | D1: Objectives | E1: DOK Level | F1: Prerequisites | G1: Key Words | H1: Suggested Lesson Vocabulary with Definitions | I1: Suggested Activities | J1: Discussion Topic | K1: Lesson Examples | L1: Helpful Notes | M1: Pennsylvania Standards | N1: California Standards | O1: Texas Standards | P1: Florida Standards | Q1: National Standards
A2: 7 | B2: Module Name Here | D2: Students will: | F2: Students must be able to:
A3: 7.1
A4: 7.2
A5: 7.3
A6: 7.4
A7: 7.5
A8: 7.6
A9: 7.7
A10: 7.8
A11: 7.9
A12: 7.10
A13: 8 | B13: Module Name Here | D13: Students will: | F13: Students must be able to:
A14: 8.1
A15: 8.2
A16: 8.3
A17: 8.4
A18: 8.5
A19: 8.6
A20: 8.7
A21: 8.8
A22: 8.9
A23: 8.10
A24: 9 | B24: Module Name Here | D24: Students will: | F24: Students must be able to:
A25: 9.1
A26: 9.2
A27: 9.3
A28: 9.4
A29: 9.5
A30: 9.6
A31: 9.7
A32: 9.8
A33: 9.9
A34: 9.10
A35: 10 | B35: Module Name Here | D35: Students will: | F35: Students must be able to:
A36: 10.1
A37: 10.2
A38: 10.3
A39: 10.4
A40: 10.5
...

Sheet Course Specs
A1: SPECIFICATION | B1: DETAILS | C1: NOTES
A2: Grade level
A3: # of semesters
A4: Total # of modules
A5: # of lessons/module
A6: Lesson length (page count)
A7: Page types
A8: # of videos
A9: Video length (audio length)
A10: Teacher-graded assignments
A11: Discussions
A12: Lesson quiz -- # of MC questions
A13: Module exam ​-- # of MC questions
... A16: Final exam ​-- # of FRQ

Sheet Additional Resources

Sheet Course Description
A1: Column1 | B1: Column2
A2: Course Title
A3: Grade Level (youngest)
A4: Materials Needed
A5: Course Length (Semesters)
A6: Pre-requisite Courses
A7: Technology Skills (special)
A8: Course Description Semester A
A9: Course Description Semester B
A10: Major Concepts (5-10) Semester A
A11: Major Concepts (5-10) Semester B

Sheet CLOs & MLOs
A1: Module | B1: Course Level Objectives | C1: Module Level Objectives | D1: DOK
B2: Module 1: Name of Module
A3: 1 | B3: Upon completion of this course, learner will… (You will want to provide an overall objective for the entire module. Each Course Learning Objective (CLO) will start with the text in black. A verb from the DOK Chart would come next and be in bold. This verb and objective needs to be considered measurable by a 3rd party source, and it must cover the entire module.) | C3: Learners will… The set up for Module Learning Objectives (MLOs) is very similar to the format of the CLOs. Keep the boiler plate text above the same for every MLO. Add a DOK chart verb(s) in bold. A suggestion would be to look at each lesson and create an overall objective of that lesson. Add as many rows here as needed.
B9: Module 2: Name of Module
A10: 2
B16: Module 3: Name of Module
A17: 3
B23: Module 4: Name of Module
A24: 4
B30: Module 5: Name of Module
A31: 5
B37: Module 6: Name of Module
A38: 6
B44: Module 7: Name of Module
A45: 7
B51: Module 8: Name of Module
A52: 8
B58: Module 9: Name of Module
A59: 9
B65: Module 10: Name of Module
A66: 10
B72: Module 11: Name of Module
A73: 11
B79: Module 12: Name of Module
A80: 12

Sheet Buzz Footprint
A1: Lesson # | B1: Lesson Title | C1: Link to Assignment | D1: Key or Rubric | E1: Worksheet? | F1: *All lessons have quizzes & All modules have exams
A2: 1
A3: 1.1 | B3: =Table1[[#This Row],[Lesson Title]] -> 0
A4: 1.2 | B4: =Table1[[#This Row],[Lesson Title]] -> 0
A5: 1.3 | B5: =Table1[[#This Row],[Lesson Title]] -> 0
A6: 1.4 | B6: =Table1[[#This Row],[Lesson Title]] -> 0
A7: 1.5 | B7: =Table1[[#This Row],[Lesson Title]] -> 0
A8: 1.6 | B8: =Table1[[#This Row],[Lesson Title]] -> 0
A9: 1.7 | B9: =Table1[[#This Row],[Lesson Title]] -> 0
A10: 1.8 | B10: =Table1[[#This Row],[Lesson Title]] -> 0
A11: 1.9 | B11: =Table1[[#This Row],[Lesson Title]] -> 0
A12: 1.10 | B12: =Table1[[#This Row],[Lesson Title]] -> 0
A13: 2
A14: 2.1 | B14: =Table1[[#This Row],[Lesson Title]] -> 0
A15: 2.2 | B15: =Table1[[#This Row],[Lesson Title]] -> 0
A16: 2.3 | B16: =Table1[[#This Row],[Lesson Title]] -> 0
A17: 2.4 | B17: =Table1[[#This Row],[Lesson Title]] -> 0
A18: 2.5 | B18: =Table1[[#This Row],[Lesson Title]] -> 0
A19: 2.6 | B19: =Table1[[#This Row],[Lesson Title]] -> 0
A20: 2.7 | B20: =Table1[[#This Row],[Lesson Title]] -> 0
A21: 2.8 | B21: =Table1[[#This Row],[Lesson Title]] -> 0
A22: 2.9 | B22: =Table1[[#This Row],[Lesson Title]] -> 0
A23: 2.10 | B23: =Table1[[#This Row],[Lesson Title]] -> 0
A24: 3
A25: 3.1 | B25: =Table1[[#This Row],[Lesson Title]] -> 0
A26: 3.2 | B26: =Table1[[#This Row],[Lesson Title]] -> 0
A27: 3.3 | B27: =Table1[[#This Row],[Lesson Title]] -> 0
A28: 3.4 | B28: =Table1[[#This Row],[Lesson Title]] -> 0
A29: 3.5 | B29: =Table1[[#This Row],[Lesson Title]] -> 0
A30: 3.6 | B30: =Table1[[#This Row],[Lesson Title]] -> 0
A31: 3.7 | B31: =Table1[[#This Row],[Lesson Title]] -> 0
A32: 3.8 | B32: =Table1[[#This Row],[Lesson Title]] -> 0
A33: 3.9 | B33: =Table1[[#This Row],[Lesson Title]] -> 0
A34: 3.10 | B34: =Table1[[#This Row],[Lesson Title]] -> 0
A35: 4
A36: 4.1 | B36: =Table1[[#This Row],[Lesson Title]] -> 0
A37: 4.2 | B37: =Table1[[#This Row],[Lesson Title]] -> 0
A38: 4.3 | B38: =Table1[[#This Row],[Lesson Title]] -> 0
A39: 4.4 | B39: =Table1[[#This Row],[Lesson Title]] -> 0
A40: 4.5 | B40: =Table1[[#This Row],[Lesson Title]] -> 0
...
